Workbook
Name Slicer_Location: #N/A
Name Slicer_Month: #N/A
Name Slicer_Payment_Type: #N/A
Name Slicer_Year: #N/A

Sheet Brand New Mobile Details Data
A1: Date | B1: Month | C1: Weekday | D1: Year | E1: Clean Customer Name | F1: Service | G1: Price | H1: Location | I1: Payment Type
A2: 45659 | B2: =TEXT('Brand New Mobile Details Data'!$A2,"MMM") -> Jan | C2: =TEXT('Brand New Mobile Details Data'!$A2,"dddd") -> Thursday | D2: =TEXT('Brand New Mobile Details Data'!$A2,"yyyy") -> 2025 | E2: Mason Price | F2: Exterior Wash | G2: 60 | H2: Venice | I2: Card
A3: 45659 | B3: =TEXT('Brand New Mobile Details Data'!$A3,"MMM") -> Jan | C3: =TEXT('Brand New Mobile Details Data'!$A3,"dddd") -> Thursday | D3: =TEXT('Brand New Mobile Details Data'!$A3,"yyyy") -> 2025 | E3: Ella Watson | F3: Full Detail | G3: 150 | H3: Port Charlotte | I3: Card
A4: 45659 | B4: =TEXT('Brand New Mobile Details Data'!$A4,"MMM") -> Jan | C4: =TEXT('Brand New Mobile Details Data'!$A4,"dddd") -> Thursday | D4: =TEXT('Brand New Mobile Details Data'!$A4,"yyyy") -> 2025 | E4: Lucas Young | F4: Exterior Wash | G4: 60 | H4: North Port | I4: Cash
A5: 45659 | B5: =TEXT('Brand New Mobile Details Data'!$A5,"MMM") -> Jan | C5: =TEXT('Brand New Mobile Details Data'!$A5,"dddd") -> Thursday | D5: =TEXT('Brand New Mobile Details Data'!$A5,"yyyy") -> 2025 | E5: Lucas Young | F5: Exterior Wash | G5: 60 | H5: North Port | I5: Card
A6: 45662 | B6: =TEXT('Brand New Mobile Details Data'!$A6,"MMM") -> Jan | C6: =TEXT('Brand New Mobile Details Data'!$A6,"dddd") -> Sunday | D6: =TEXT('Brand New Mobile Details Data'!$A6,"yyyy") -> 2025 | E6: Lucas Young | F6: Headlight Restoration | G6: 70 | H6: North Port | I6: Cash
A7: 45664 | B7: =TEXT('Brand New Mobile Details Data'!$A7,"MMM") -> Jan | C7: =TEXT('Brand New Mobile Details Data'!$A7,"dddd") -> Tuesday | D7: =TEXT('Brand New Mobile Details Data'!$A7,"yyyy") -> 2025 | E7: Nora Evans | F7: Full Detail | G7: 150 | H7: Port Charlotte | I7: Card
A8: 45667 | B8: =TEXT('Brand New Mobile Details Data'!$A8,"MMM") -> Jan | C8: =TEXT('Brand New Mobile Details Data'!$A8,"dddd") -> Friday | D8: =TEXT('Brand New Mobile Details Data'!$A8,"yyyy") -> 2025 | E8: George Grant | F8: Full Detail | G8: 150 | H8: North Port | I8: Card
A9: 45667 | B9: =TEXT('Brand New Mobile Details Data'!$A9,"MMM") -> Jan | C9: =TEXT('Brand New Mobile Details Data'!$A9,"dddd") -> Friday | D9: =TEXT('Brand New Mobile Details Data'!$A9,"yyyy") -> 2025 | E9: Jackson Moore | F9: Full Detail | G9: 150 | H9: Venice | I9: Card
A10: 45668 | B10: =TEXT('Brand New Mobile Details Data'!$A10,"MMM") -> Jan | C10: =TEXT('Brand New Mobile Details Data'!$A10,"dddd") -> Saturday | D10: =TEXT('Brand New Mobile Details Data'!$A10,"yyyy") -> 2025 | E10: Liam Carter | F10: Exterior Wash | G10: 60 | H10: Venice | I10: Card
A11: 45669 | B11: =TEXT('Brand New Mobile Details Data'!$A11,"MMM") -> Jan | C11: =TEXT('Brand New Mobile Details Data'!$A11,"dddd") -> Sunday | D11: =TEXT('Brand New Mobile Details Data'!$A11,"yyyy") -> 2025 | E11: Isabella Scott | F11: Interior Detail | G11: 120 | H11: Sarasota | I11: Mobile Pay
A12: 45671 | B12: =TEXT('Brand New Mobile Details Data'!$A12,"MMM") -> Jan | C12: =TEXT('Brand New Mobile Details Data'!$A12,"dddd") -> Tuesday | D12: =TEXT('Brand New Mobile Details Data'!$A12,"yyyy") -> 2025 | E12: James Miller | F12: Interior Detail | G12: 120 | H12: Venice | I12: Cash
A13: 45675 | B13: =TEXT('Brand New Mobile Details Data'!$A13,"MMM") -> Jan | C13: =TEXT('Brand New Mobile Details Data'!$A13,"dddd") -> Saturday | D13: =TEXT('Brand New Mobile Details Data'!$A13,"yyyy") -> 2025 | E13: Jacob Reed | F13: Interior Detail | G13: 120 | H13: Sarasota | I13: Cash
... A301: 46021 | B301: =TEXT('Brand New Mobile Details Data'!$A301,"MMM") -> Dec | C301: =TEXT('Brand New Mobile Details Data'!$A301,"dddd") -> Tuesday | D301: =TEXT('Brand New Mobile Details Data'!$A301,"yyyy") -> 2025 | E301: James Miller | F301: Interior Detail | G301: 120 | H301: Sarasota | I301: Card

Sheet Dashboard
A2: Brand New Mobile Detail
A3: 2025 Analytics Dashboard
B100: Row Labels | C100: Sum of Price | E100: Row Labels | F100: Sum of Price | H100: Row Labels | I100: Sum of Price
B101: James Miller | C101: 1430 | E101: Jan | F101: 1990 | H101: Engine Bay Cleaning | I101: 4560 | K101: Row Labels | L101: Sum of Price | R101: Row Labels | S101: Count of Payment Type
B102: Evelyn Reed | C102: 1140 | E102: Feb | F102: 2600 | H102: Exterior Wash | I102: 3240 | K102: Englewood | L102: 5980 | R102: Card | S102: 101
B103: Harper Cole | C103: 1090 | E103: Mar | F103: 2180 | H103: Full Detail | I103: 9000 | K103: North Port | L103: 6430 | R103: Cash | S103: 111
B104: Isabella Scott | C104: 1070 | E104: Apr | F104: 1910 | H104: Headlight Restoration | I104: 4480 | K104: Port Charlotte | L104: 5390 | R104: Mobile Pay | S104: 88
B105: Eddie Jordan | C105: 1040 | E105: May | F105: 2750 | H105: Interior Detail | I105: 7800 | K105: Sarasota | L105: 5290 | R105: Grand Total | S105: 300
B106: Michael Brown | C106: 920 | E106: Jun | F106: 3690 | H106: Grand Total | I106: 29080 | K106: Venice | L106: 5990
B107: Danny Wilson | C107: 890 | E107: Jul | F107: 3700 | K107: Grand Total | L107: 29080
B108: Henry Scott | C108: 880 | E108: Aug | F108: 2030
B109: Mason Collins | C109: 860 | E109: Sep | F109: 1790 | H109: Row Labels | I109: Sum of Price | J109: Count of Service | K109: Average of Price2
B110: Nora Evans | C110: 820 | E110: Oct | F110: 2240 | H110: 60 | I110: 3240 | J110: 54 | K110: 60 | M110: Row Labels | N110: Count of Service
B111: Carter James | C111: 800 | E111: Nov | F111: 2220 | H111: Exterior Wash | I111: 3240 | J111: 54 | K111: 60 | M111: Interior Detail | N111: 65
B112: Ethan Hughes | C112: 800 | E112: Dec | F112: 1980 | H112: 70 | I112: 4480 | J112: 64 | K112: 70 | M112: Headlight Restoration | N112: 64
B113: Oliver Adams | C113: 760 | E113: Grand Total | F113: 29080 | H113: Headlight Restoration | I113: 4480 | J113: 64 | K113: 70 | M113: Full Detail | N113: 60
B114: Liam Carter | C114: 740 | H114: 80 | I114: 4560 | J114: 57 | K114: 80 | M114: Engine Bay Cleaning | N114: 57
B115: Anthony Davis | C115: 720 | H115: Engine Bay Cleaning | I115: 4560 | J115: 57 | K115: 80 | M115: Exterior Wash | N115: 54
B116: Ava Mitchell | C116: 710 | H116: 120 | I116: 7800 | J116: 65 | K116: 120 | M116: Grand Total | N116: 300
B117: Aubrey Kelly | C117: 680 | H117: Interior Detail | I117: 7800 | J117: 65 | K117: 120
B118: Emily Clark | C118: 610 | H118: 150 | I118: 9000 | J118: 60 | K118: 150
B119: Brian King | C119: 600 | H119: Full Detail | I119: 9000 | J119: 60 | K119: 150
B120: Jacob Reed | C120: 590 | H120: Grand Total | I120: 29080 | J120: 300 | K120: 96.933333
B121: Elijah Brooks | C121: 580 | M121: Row Labels | N121: Count of Location
B122: Lucas Young | C122: 550 | M122: North Port | N122: 71
B123: Sarah Lee | C123: 540 | M123: Englewood | N123: 60
B124: Logan Parker | C124: 540 | M124: Venice | N124: 59
B125: Lucas Wright | C125: 530 | M125: Port Charlotte | N125: 56
B126: Ella Watson | C126: 520 | M126: Sarasota | N126: 54
B127: Emma White | C127: 520 | M127: Grand Total | N127: 300
B128: Victor Stone | C128: 520
B129: Charlotte Turner | C129: 490
B130: Noah Johnson | C130: 480
B131: Jackson Moore | C131: 480
B132: Grace Reed | C132: 480
B133: Amelia Rivera | C133: 470
B134: Alex Knight | C134: 470
B135: Mason Price | C135: 440
B136: Olivia Green | C136: 420
B137: John Doe | C137: 420
...
